[2023-10-01 11:35:27] [INFO    ] discord.client: logging in using static token
[2023-10-01 11:35:29] [INFO    ] discord.gateway: Shard ID None has connected to Gateway (Session ID: b7268ce10291176f5e69a856472fa1d2).
[2023-10-01 12:42:54] [INFO    ] discord.gateway: Shard ID None has successfully RESUMED session b7268ce10291176f5e69a856472fa1d2.
[2023-10-01 13:14:33] [INFO    ] discord.gateway: Shard ID None has successfully RESUMED session b7268ce10291176f5e69a856472fa1d2.
[2023-10-01 14:26:20] [INFO    ] discord.gateway: Shard ID None has successfully RESUMED session b7268ce10291176f5e69a856472fa1d2.
[2023-10-01 17:36:58] [INFO    ] discord.gateway: Shard ID None has successfully RESUMED session b7268ce10291176f5e69a856472fa1d2.
[2023-10-01 18:44:10] [ERROR   ] discord.client: Attempting a reconnect in 1.40s
Traceback (most recent call last):
  File "C:\Users\20220814\anaconda3\envs\DiscordBot\Lib\site-packages\aiohttp\connector.py", line 1155, in _create_direct_connection
    hosts = await asyncio.shield(host_resolved)
            ^^^^^^^^^^^^^^^^^^^^^^^^^^^^^^^^^^^
  File "C:\Users\20220814\anaconda3\envs\DiscordBot\Lib\site-packages\aiohttp\connector.py", line 874, in _resolve_host
    addrs = await self._resolver.resolve(host, port, family=self._family)
            ^^^^^^^^^^^^^^^^^^^^^^^^^^^^^^^^^^^^^^^^^^^^^^^^^^^^^^^^^^^^^
  File "C:\Users\20220814\anaconda3\envs\DiscordBot\Lib\site-packages\aiohttp\resolver.py", line 33, in resolve
    infos = await self._loop.getaddrinfo(
            ^^^^^^^^^^^^^^^^^^^^^^^^^^^^^
  File "C:\Users\20220814\anaconda3\envs\DiscordBot\Lib\asyncio\base_events.py", line 867, in getaddrinfo
    return await self.run_in_executor(
           ^^^^^^^^^^^^^^^^^^^^^^^^^^^
  File "C:\Users\20220814\anaconda3\envs\DiscordBot\Lib\concurrent\futures\thread.py", line 58, in run
    result = self.fn(*self.args, **self.kwargs)
             ^^^^^^^^^^^^^^^^^^^^^^^^^^^^^^^^^^
  File "C:\Users\20220814\anaconda3\envs\DiscordBot\Lib\socket.py", line 962, in getaddrinfo
    for res in _socket.getaddrinfo(host, port, family, type, proto, flags):
               ^^^^^^^^^^^^^^^^^^^^^^^^^^^^^^^^^^^^^^^^^^^^^^^^^^^^^^^^^^^
socket.gaierror: [Errno 11001] getaddrinfo failed

The above exception was the direct cause of the following exception:

Traceback (most recent call last):
  File "C:\Users\20220814\anaconda3\envs\DiscordBot\Lib\site-packages\discord\client.py", line 656, in connect
    self.ws = await asyncio.wait_for(coro, timeout=60.0)
              ^^^^^^^^^^^^^^^^^^^^^^^^^^^^^^^^^^^^^^^^^^
  File "C:\Users\20220814\anaconda3\envs\DiscordBot\Lib\asyncio\tasks.py", line 479, in wait_for
    return fut.result()
           ^^^^^^^^^^^^
  File "C:\Users\20220814\anaconda3\envs\DiscordBot\Lib\site-packages\discord\gateway.py", line 372, in from_client
    socket = await client.http.ws_connect(str(url))
             ^^^^^^^^^^^^^^^^^^^^^^^^^^^^^^^^^^^^^^
  File "C:\Users\20220814\anaconda3\envs\DiscordBot\Lib\site-packages\discord\http.py", line 537, in ws_connect
    return await self.__session.ws_connect(url, **kwargs)
           ^^^^^^^^^^^^^^^^^^^^^^^^^^^^^^^^^^^^^^^^^^^^^^
  File "C:\Users\20220814\anaconda3\envs\DiscordBot\Lib\site-packages\aiohttp\client.py", line 779, in _ws_connect
    resp = await self.request(
           ^^^^^^^^^^^^^^^^^^^
  File "C:\Users\20220814\anaconda3\envs\DiscordBot\Lib\site-packages\aiohttp\client.py", line 536, in _request
    conn = await self._connector.connect(
           ^^^^^^^^^^^^^^^^^^^^^^^^^^^^^^
  File "C:\Users\20220814\anaconda3\envs\DiscordBot\Lib\site-packages\aiohttp\connector.py", line 540, in connect
    proto = await self._create_connection(req, traces, timeout)
            ^^^^^^^^^^^^^^^^^^^^^^^^^^^^^^^^^^^^^^^^^^^^^^^^^^^
  File "C:\Users\20220814\anaconda3\envs\DiscordBot\Lib\site-packages\aiohttp\connector.py", line 901, in _create_connection
    _, proto = await self._create_direct_connection(req, traces, timeout)
               ^^^^^^^^^^^^^^^^^^^^^^^^^^^^^^^^^^^^^^^^^^^^^^^^^^^^^^^^^^
  File "C:\Users\20220814\anaconda3\envs\DiscordBot\Lib\site-packages\aiohttp\connector.py", line 1169, in _create_direct_connection
    raise ClientConnectorError(req.connection_key, exc) from exc
aiohttp.client_exceptions.ClientConnectorError: Cannot connect to host gateway-us-east1-b.discord.gg:443 ssl:default [getaddrinfo failed]
[2023-10-01 18:44:15] [INFO    ] discord.gateway: Shard ID None has successfully RESUMED session b7268ce10291176f5e69a856472fa1d2.
[2023-10-01 22:21:17] [INFO    ] discord.gateway: Shard ID None has successfully RESUMED session b7268ce10291176f5e69a856472fa1d2.
[2023-10-01 22:41:25] [INFO    ] discord.gateway: Shard ID None has successfully RESUMED session b7268ce10291176f5e69a856472fa1d2.
[2023-10-02 01:59:44] [INFO    ] discord.gateway: Shard ID None has successfully RESUMED session b7268ce10291176f5e69a856472fa1d2.
[2023-10-02 02:48:32] [INFO    ] discord.gateway: Shard ID None has successfully RESUMED session b7268ce10291176f5e69a856472fa1d2.
[2023-10-02 03:57:14] [WARNING ] discord.gateway: Shard ID None has stopped responding to the gateway. Closing and restarting.
[2023-10-02 03:57:14] [INFO    ] discord.gateway: Shard ID None session has been invalidated.
[2023-10-02 03:57:20] [INFO    ] discord.gateway: Shard ID None has connected to Gateway (Session ID: b9e1a248c110e9a414a122101570af85).
[2023-10-02 04:24:36] [INFO    ] discord.gateway: Shard ID None has successfully RESUMED session b9e1a248c110e9a414a122101570af85.
[2023-10-02 05:43:25] [INFO    ] discord.gateway: Shard ID None has successfully RESUMED session b9e1a248c110e9a414a122101570af85.
[2023-10-02 06:13:41] [INFO    ] discord.gateway: Shard ID None has successfully RESUMED session b9e1a248c110e9a414a122101570af85.
[2023-10-02 06:25:23] [INFO    ] discord.gateway: Shard ID None has successfully RESUMED session b9e1a248c110e9a414a122101570af85.
[2023-10-02 08:41:36] [INFO    ] discord.gateway: Shard ID None has successfully RESUMED session b9e1a248c110e9a414a122101570af85.
[2023-10-02 08:43:21] [INFO    ] discord.gateway: Shard ID None has successfully RESUMED session b9e1a248c110e9a414a122101570af85.
