[2023-11-28 16:30:59] [INFO    ] discord.client: logging in using static token
[2023-11-28 16:31:01] [INFO    ] discord.gateway: Shard ID None has connected to Gateway (Session ID: c89f1adc9e147677b4ccc124dbb8f22b).
[2023-12-05 12:30:25] [ERROR   ] discord.client: Attempting a reconnect in 1.14s
Traceback (most recent call last):
  File "C:\Users\leozh\anaconda3\envs\DiscordBot\Lib\site-packages\aiohttp\connector.py", line 1155, in _create_direct_connection
    hosts = await asyncio.shield(host_resolved)
            ^^^^^^^^^^^^^^^^^^^^^^^^^^^^^^^^^^^
  File "C:\Users\leozh\anaconda3\envs\DiscordBot\Lib\site-packages\aiohttp\connector.py", line 874, in _resolve_host
    addrs = await self._resolver.resolve(host, port, family=self._family)
            ^^^^^^^^^^^^^^^^^^^^^^^^^^^^^^^^^^^^^^^^^^^^^^^^^^^^^^^^^^^^^
  File "C:\Users\leozh\anaconda3\envs\DiscordBot\Lib\site-packages\aiohttp\resolver.py", line 33, in resolve
    infos = await self._loop.getaddrinfo(
            ^^^^^^^^^^^^^^^^^^^^^^^^^^^^^
  File "C:\Users\leozh\anaconda3\envs\DiscordBot\Lib\asyncio\base_events.py", line 867, in getaddrinfo
    return await self.run_in_executor(
           ^^^^^^^^^^^^^^^^^^^^^^^^^^^
  File "C:\Users\leozh\anaconda3\envs\DiscordBot\Lib\concurrent\futures\thread.py", line 58, in run
    result = self.fn(*self.args, **self.kwargs)
             ^^^^^^^^^^^^^^^^^^^^^^^^^^^^^^^^^^
  File "C:\Users\leozh\anaconda3\envs\DiscordBot\Lib\socket.py", line 962, in getaddrinfo
    for res in _socket.getaddrinfo(host, port, family, type, proto, flags):
               ^^^^^^^^^^^^^^^^^^^^^^^^^^^^^^^^^^^^^^^^^^^^^^^^^^^^^^^^^^^
socket.gaierror: [Errno 11001] getaddrinfo failed

The above exception was the direct cause of the following exception:

Traceback (most recent call last):
  File "C:\Users\leozh\anaconda3\envs\DiscordBot\Lib\site-packages\discord\client.py", line 656, in connect
    self.ws = await asyncio.wait_for(coro, timeout=60.0)
              ^^^^^^^^^^^^^^^^^^^^^^^^^^^^^^^^^^^^^^^^^^
  File "C:\Users\leozh\anaconda3\envs\DiscordBot\Lib\asyncio\tasks.py", line 479, in wait_for
    return fut.result()
           ^^^^^^^^^^^^
  File "C:\Users\leozh\anaconda3\envs\DiscordBot\Lib\site-packages\discord\gateway.py", line 372, in from_client
    socket = await client.http.ws_connect(str(url))
             ^^^^^^^^^^^^^^^^^^^^^^^^^^^^^^^^^^^^^^
  File "C:\Users\leozh\anaconda3\envs\DiscordBot\Lib\site-packages\discord\http.py", line 537, in ws_connect
    return await self.__session.ws_connect(url, **kwargs)
           ^^^^^^^^^^^^^^^^^^^^^^^^^^^^^^^^^^^^^^^^^^^^^^
  File "C:\Users\leozh\anaconda3\envs\DiscordBot\Lib\site-packages\aiohttp\client.py", line 779, in _ws_connect
    resp = await self.request(
           ^^^^^^^^^^^^^^^^^^^
  File "C:\Users\leozh\anaconda3\envs\DiscordBot\Lib\site-packages\aiohttp\client.py", line 536, in _request
    conn = await self._connector.connect(
           ^^^^^^^^^^^^^^^^^^^^^^^^^^^^^^
  File "C:\Users\leozh\anaconda3\envs\DiscordBot\Lib\site-packages\aiohttp\connector.py", line 540, in connect
    proto = await self._create_connection(req, traces, timeout)
            ^^^^^^^^^^^^^^^^^^^^^^^^^^^^^^^^^^^^^^^^^^^^^^^^^^^
  File "C:\Users\leozh\anaconda3\envs\DiscordBot\Lib\site-packages\aiohttp\connector.py", line 901, in _create_connection
    _, proto = await self._create_direct_connection(req, traces, timeout)
               ^^^^^^^^^^^^^^^^^^^^^^^^^^^^^^^^^^^^^^^^^^^^^^^^^^^^^^^^^^
  File "C:\Users\leozh\anaconda3\envs\DiscordBot\Lib\site-packages\aiohttp\connector.py", line 1169, in _create_direct_connection
    raise ClientConnectorError(req.connection_key, exc) from exc
aiohttp.client_exceptions.ClientConnectorError: Cannot connect to host gateway-us-east1-b.discord.gg:443 ssl:default [getaddrinfo failed]
[2023-12-05 12:30:26] [ERROR   ] discord.client: Attempting a reconnect in 2.31s
Traceback (most recent call last):
  File "C:\Users\leozh\anaconda3\envs\DiscordBot\Lib\site-packages\aiohttp\connector.py", line 1155, in _create_direct_connection
    hosts = await asyncio.shield(host_resolved)
            ^^^^^^^^^^^^^^^^^^^^^^^^^^^^^^^^^^^
  File "C:\Users\leozh\anaconda3\envs\DiscordBot\Lib\site-packages\aiohttp\connector.py", line 874, in _resolve_host
    addrs = await self._resolver.resolve(host, port, family=self._family)
            ^^^^^^^^^^^^^^^^^^^^^^^^^^^^^^^^^^^^^^^^^^^^^^^^^^^^^^^^^^^^^
  File "C:\Users\leozh\anaconda3\envs\DiscordBot\Lib\site-packages\aiohttp\resolver.py", line 33, in resolve
    infos = await self._loop.getaddrinfo(
            ^^^^^^^^^^^^^^^^^^^^^^^^^^^^^
  File "C:\Users\leozh\anaconda3\envs\DiscordBot\Lib\asyncio\base_events.py", line 867, in getaddrinfo
    return await self.run_in_executor(
           ^^^^^^^^^^^^^^^^^^^^^^^^^^^
  File "C:\Users\leozh\anaconda3\envs\DiscordBot\Lib\concurrent\futures\thread.py", line 58, in run
    result = self.fn(*self.args, **self.kwargs)
             ^^^^^^^^^^^^^^^^^^^^^^^^^^^^^^^^^^
  File "C:\Users\leozh\anaconda3\envs\DiscordBot\Lib\socket.py", line 962, in getaddrinfo
    for res in _socket.getaddrinfo(host, port, family, type, proto, flags):
               ^^^^^^^^^^^^^^^^^^^^^^^^^^^^^^^^^^^^^^^^^^^^^^^^^^^^^^^^^^^
socket.gaierror: [Errno 11001] getaddrinfo failed

The above exception was the direct cause of the following exception:

Traceback (most recent call last):
  File "C:\Users\leozh\anaconda3\envs\DiscordBot\Lib\site-packages\discord\client.py", line 656, in connect
    self.ws = await asyncio.wait_for(coro, timeout=60.0)
              ^^^^^^^^^^^^^^^^^^^^^^^^^^^^^^^^^^^^^^^^^^
  File "C:\Users\leozh\anaconda3\envs\DiscordBot\Lib\asyncio\tasks.py", line 479, in wait_for
    return fut.result()
           ^^^^^^^^^^^^
  File "C:\Users\leozh\anaconda3\envs\DiscordBot\Lib\site-packages\discord\gateway.py", line 372, in from_client
    socket = await client.http.ws_connect(str(url))
             ^^^^^^^^^^^^^^^^^^^^^^^^^^^^^^^^^^^^^^
  File "C:\Users\leozh\anaconda3\envs\DiscordBot\Lib\site-packages\discord\http.py", line 537, in ws_connect
    return await self.__session.ws_connect(url, **kwargs)
           ^^^^^^^^^^^^^^^^^^^^^^^^^^^^^^^^^^^^^^^^^^^^^^
  File "C:\Users\leozh\anaconda3\envs\DiscordBot\Lib\site-packages\aiohttp\client.py", line 779, in _ws_connect
    resp = await self.request(
           ^^^^^^^^^^^^^^^^^^^
  File "C:\Users\leozh\anaconda3\envs\DiscordBot\Lib\site-packages\aiohttp\client.py", line 536, in _request
    conn = await self._connector.connect(
           ^^^^^^^^^^^^^^^^^^^^^^^^^^^^^^
  File "C:\Users\leozh\anaconda3\envs\DiscordBot\Lib\site-packages\aiohttp\connector.py", line 540, in connect
    proto = await self._create_connection(req, traces, timeout)
            ^^^^^^^^^^^^^^^^^^^^^^^^^^^^^^^^^^^^^^^^^^^^^^^^^^^
  File "C:\Users\leozh\anaconda3\envs\DiscordBot\Lib\site-packages\aiohttp\connector.py", line 901, in _create_connection
    _, proto = await self._create_direct_connection(req, traces, timeout)
               ^^^^^^^^^^^^^^^^^^^^^^^^^^^^^^^^^^^^^^^^^^^^^^^^^^^^^^^^^^
  File "C:\Users\leozh\anaconda3\envs\DiscordBot\Lib\site-packages\aiohttp\connector.py", line 1169, in _create_direct_connection
    raise ClientConnectorError(req.connection_key, exc) from exc
aiohttp.client_exceptions.ClientConnectorError: Cannot connect to host gateway-us-east1-b.discord.gg:443 ssl:default [getaddrinfo failed]
[2023-12-05 12:30:29] [INFO    ] discord.gateway: Shard ID None session has been invalidated.
[2023-12-05 12:30:35] [INFO    ] discord.gateway: Shard ID None has connected to Gateway (Session ID: 1add1c6a6c17bc3e4396c58ddbfb6aa8).
